<mujoco model="bipedal10.2">
  <compiler angle="radian" meshdir="meshes"/>
  <size njmax="500" nconmax="100" />
  <asset>
    <mesh name="base_link" file="base_link.STL"/>
    <mesh name="FixMotor1" file="FixMotor1.STL"/>
    <mesh name="FixMotor3" file="FixMotor3.STL"/>
    <mesh name="R1" file="R1.STL"/>
    <mesh name="FixMotor4" file="FixMotor4.STL"/>
    <mesh name="R2" file="R2.STL"/>
    <mesh name="R3" file="R3.STL"/>
    <mesh name="R4" file="R4.STL"/>
    <mesh name="L1" file="L1.STL"/>
    <mesh name="FixMotor2" file="FixMotor2.STL"/>
    <mesh name="L2" file="L2.STL"/>
    <mesh name="L3" file="L3.STL"/>
    <mesh name="L4" file="L4.STL"/>
  </asset>

  <worldbody>
    <!-- <geom name="floor" type="plane" pos = '0 0 -0.5' size="10 10 0.1" rgba="1 1 1 1" material="" condim="3" friction="0.9 0.1 0.1"/>
    <light name="bright_light" pos="0 0 10" dir="0 0 -1" diffuse="0.3 0.3 0.3" specular="1 1 1" ambient="0.1 0.1 0.1" mode="trackcom" /> -->

    <body name="base_link">
      <inertial pos="-0.0430455 0.0467319 -0.0223114" quat="0.49877 0.501535 -0.497211 0.502467" mass="0.9138" diaginertia="0.000918252 0.000530322 0.000437595"/>
      <joint name="floating_base" type="free" limited="false" actuatorfrclimited="false"/>
      <geom type="mesh" contype="0" conaffinity="0" group="1" density="0" rgba="0.92549 0.92549 0.90588 1" mesh="base_link"/>
      <geom type="mesh" rgba="0.92549 0.92549 0.90588 1" mesh="base_link"/>
      <geom pos="-0.092323 0.070189 -0.020612" quat="1 0 0 0" type="mesh" contype="0" conaffinity="0" group="1" density="0" rgba="0.29804 0.29804 0.29804 1" mesh="FixMotor1"/>
      <geom pos="-0.092323 0.070189 -0.020612" quat="1 0 0 0" type="mesh" rgba="0.29804 0.29804 0.29804 1" mesh="FixMotor1"/>
      <geom pos="0.0060771 0.070189 -0.020612" quat="0.707105 0 0.707108 0" type="mesh" contype="0" conaffinity="0" group="1" density="0" rgba="0.29804 0.29804 0.29804 1" mesh="FixMotor3"/>
      <geom pos="0.0060771 0.070189 -0.020612" quat="0.707105 0 0.707108 0" type="mesh" rgba="0.29804 0.29804 0.29804 1" mesh="FixMotor3"/>
      
      <site name="imu" pos="0 0 0"/>
      
      <body name="R1" pos="0.024227 0.059189 -0.020612" quat="0.707105 0 0 0.707108">
        <inertial pos="5.04629e-06 -0.0200582 -0.0616403" quat="0.99416 -0.107403 0.00950229 -0.00442741" mass="0.0988" diaginertia="9.67921e-05 8.19704e-05 3.52418e-05"/>
        <joint name="R1" pos="0 0 0" axis="0 1 0"/>
        <geom type="mesh" contype="0" conaffinity="0" group="1" density="0" rgba="0.62745 0.62745 0.62745 1" mesh="R1"/>
        <geom type="mesh" rgba="0.62745 0.62745 0.62745 1" mesh="R1"/>
        <geom pos="-0.00028834 -0.024 -0.0905" quat="0.707105 -0.707107 0.00112645 0.00112646" type="mesh" contype="0" conaffinity="0" group="1" density="0" rgba="0.29804 0.29804 0.29804 1" mesh="FixMotor4"/>
        <geom pos="-0.00028834 -0.024 -0.0905" quat="0.707105 -0.707107 0.00112645 0.00112646" type="mesh" rgba="0.29804 0.29804 0.29804 1" mesh="FixMotor4"/>
        <body name="R2" pos="-0.00038233 -0.0108 -0.12">
          <inertial pos="0.00180316 0.0014693 -0.094557" quat="0.725466 -0.0175874 0.0102784 0.687956" mass="0.0817" diaginertia="0.000211507 0.00020507 9.25785e-06"/>
          <joint name="R2" pos="0 0 0" axis="0 -1 0"/>
          <geom type="mesh" contype="0" conaffinity="0" group="1" density="0" rgba="0.43137 0.43137 0.43137 1" mesh="R2"/>
          <geom type="mesh" rgba="0.43137 0.43137 0.43137 1" mesh="R2"/>
          <geom pos="0.0024572 -0.0235 -0.11997" quat="0.350331 0.61422 0.614222 0.350333" type="mesh" contype="0" conaffinity="0" group="1" density="0" rgba="0.75294 0.75294 0.75294 1" mesh="R3"/>
          <geom pos="0.0024572 -0.0235 -0.11997" quat="0.350331 0.61422 0.614222 0.350333" type="mesh" rgba="0.75294 0.75294 0.75294 1" mesh="R3"/>
          <body name="R4" pos="0.0024572 -0.0235 -0.11997" quat="1 -2.0924e-06 3.6732e-06 9.01663e-07">
            <inertial pos="-5.703e-12 0.0065924 2.0318e-12" quat="0.707107 0 0 0.707107" mass="0.0545" diaginertia="2.4575e-05 1.3633e-05 1.3633e-05"/>
            <joint name="R4" pos="0 0 0" axis="0 1 0"/>
            <geom type="mesh" contype="0" conaffinity="0" group="1" density="0" rgba="0.50196 0.50196 0.50196 1" mesh="R4"/>
            <geom type="mesh" rgba="0.50196 0.50196 0.50196 1" mesh="R4"/>
          </body>
        </body>
      </body>
      <body name="L1" pos="-0.11057 0.059189 -0.020612" quat="0.707105 0 0 0.707108">
        <inertial pos="-0.000122144 0.020055 -0.0616402" quat="0.994142 0.10746 0.0103632 0.00516376" mass="0.0988" diaginertia="9.68031e-05 8.19712e-05 3.52522e-05"/>
        <joint name="L1" pos="0 0 0" axis="0 1 0"/>
        <geom type="mesh" contype="0" conaffinity="0" group="1" density="0" rgba="0.62745 0.62745 0.62745 1" mesh="L1"/>
        <geom type="mesh" rgba="0.62745 0.62745 0.62745 1" mesh="L1"/>
        <geom pos="-0.00044938 0.024 -0.090499" quat="0.00175297 0.00175816 -0.707106 0.707103" type="mesh" contype="0" conaffinity="0" group="1" density="0" rgba="0.29804 0.29804 0.29804 1" mesh="FixMotor2"/>
        <geom pos="-0.00044938 0.024 -0.090499" quat="0.00175297 0.00175816 -0.707106 0.707103" type="mesh" rgba="0.29804 0.29804 0.29804 1" mesh="FixMotor2"/>
        <body name="L2" pos="-0.00059586 0.0108 -0.12">
          <inertial pos="0.00202464 -0.0014693 -0.0946588" quat="0.690032 0.009635 -0.0182278 0.723485" mass="0.0817" diaginertia="0.00021192 0.000205525 9.21289e-06"/>
          <joint name="L2" pos="0 0 0" axis="0 -1 0"/>
          <geom type="mesh" contype="0" conaffinity="0" group="1" density="0" rgba="0.43137 0.43137 0.43137 1" mesh="L2"/>
          <geom type="mesh" rgba="0.43137 0.43137 0.43137 1" mesh="L2"/>
          <geom pos="0.0031907 0.0235 -0.11996" quat="0.142764 0.692544 -0.692546 -0.142764" type="mesh" contype="0" conaffinity="0" group="1" density="0" rgba="0.75294 0.75294 0.75294 1" mesh="L3"/>
          <geom pos="0.0031907 0.0235 -0.11996" quat="0.142764 0.692544 -0.692546 -0.142764" type="mesh" rgba="0.75294 0.75294 0.75294 1" mesh="L3"/>
          <body name="L4" pos="0.0031907 0.0235 -0.11996" quat="-1 -4.39955e-06 -6.32679e-06 1.4975e-07">
            <inertial pos="3.8845e-12 -0.0065924 -5.6056e-12" quat="0.707107 0 0 0.707107" mass="0.0545" diaginertia="2.4575e-05 1.3633e-05 1.3633e-05"/>
            <joint name="L4" pos="0 0 0" axis="0 1 0"/>
            <geom type="mesh" contype="0" conaffinity="0" group="1" density="0" rgba="0.50196 0.50196 0.50196 1" mesh="L4"/>
            <geom type="mesh" rgba="0.50196 0.50196 0.50196 1" mesh="L4"/>
          </body>
        </body>
      </body>
    </body>
  </worldbody>
  <actuator>
      <position name = "right_1" ctrlrange="-4 4" joint = "joint_right_1" kp = "15" kv = "0.01"/>
      <position name = "left_1" ctrlrange="-4 4" joint = "joint_left_1" kp = "15" kv = "0.01"/>
      <position name = "right_2" ctrlrange="-4 4" joint = "joint_right_2" kp = "2" kv = "0.1"/>
      <position name = "left_2" ctrlrange="-4 4" joint = "joint_left_2" kp = "2" kv = "0.1"/>
      <!-- <motor name = "right_1" joint = "joint_right_1" ctrlrange="-3 3"/>
      <motor name = "left_1"  joint = "joint_left_1"  ctrlrange="-3 3"/>
      <motor name = "right_2" joint = "joint_right_2" ctrlrange="-3 3"/>
      <motor name = "left_2"  joint = "joint_left_2"  ctrlrange="-3 3"/> -->
      <motor name = "left_3"  joint = "joint_left_3"  ctrlrange="-3 3"/>
      <motor name = "right_3" joint = "joint_right_3" ctrlrange="-3 3"/>

  </actuator>

  <sensor>
      <jointpos name="right1_pos" joint="joint_right_1" />
      <jointpos name="left1_pos"  joint="joint_left_1" />
      <jointpos name="right2_pos" joint="joint_right_2" />
      <jointpos name="left2_pos"  joint="joint_left_2" />
      <jointpos name="right3_pos" joint="joint_right_3" />
      <jointpos name="left3_pos"  joint="joint_left_3" />

      <jointvel name="right1_vel" joint="joint_right_1" />
      <jointvel name="left1_vel"  joint="joint_left_1" />
      <jointvel name="right2_vel" joint="joint_right_2" />
      <jointvel name="left2_vel"  joint="joint_left_2" />
      <jointvel name="right3_vel" joint="joint_right_3" />
      <jointvel name="left3_vel"  joint="joint_left_3" />

      <jointactuatorfrc name="right1_torque" joint="joint_right_1" />
      <jointactuatorfrc name="left1_torque"  joint="joint_left_1" />
      <jointactuatorfrc name="right2_torque" joint="joint_right_2" />
      <jointactuatorfrc name="left2_torque"  joint="joint_left_2" />
      <jointactuatorfrc name="right3_torque" joint="joint_right_3" />
      <jointactuatorfrc name="left3_torque"  joint="joint_left_3" />

      <framequat name="imu_quat" objtype="site" objname="imu" />
      <gyro name="imu_gyro" site="imu" />
      <accelerometer name="imu_acc" site="imu" />
      
      <framepos name="frame_pos" objtype="site" objname="imu" />
      <framelinvel name="frame_vel" objtype="site" objname="imu" />
  </sensor>
</mujoco>
